[2024-12-06T20:32:58.346+0000] {local_task_job_runner.py:123} INFO - ::group::Pre task execution logs
[2024-12-06T20:32:58.362+0000] {taskinstance.py:2613} INFO - Dependencies all met for dep_context=non-requeueable deps ti=<TaskInstance: homework_dag.download_dataset scheduled__2021-01-05T06:00:00+00:00 [queued]>
[2024-12-06T20:32:58.369+0000] {taskinstance.py:2613} INFO - Dependencies all met for dep_context=requeueable deps ti=<TaskInstance: homework_dag.download_dataset scheduled__2021-01-05T06:00:00+00:00 [queued]>
[2024-12-06T20:32:58.369+0000] {taskinstance.py:2866} INFO - Starting attempt 5 of 5
[2024-12-06T20:32:58.394+0000] {taskinstance.py:2889} INFO - Executing <Task(BashOperator): download_dataset> on 2021-01-05 06:00:00+00:00
[2024-12-06T20:32:58.404+0000] {warnings.py:112} WARNING - /home/***/.local/lib/python3.12/site-packages/***/task/task_runner/standard_task_runner.py:70: DeprecationWarning: This process (pid=4410) is multi-threaded, use of fork() may lead to deadlocks in the child.
  pid = os.fork()

[2024-12-06T20:32:58.410+0000] {standard_task_runner.py:72} INFO - Started process 4414 to run task
[2024-12-06T20:32:58.409+0000] {standard_task_runner.py:104} INFO - Running: ['***', 'tasks', 'run', 'homework_dag', 'download_dataset', 'scheduled__2021-01-05T06:00:00+00:00', '--job-id', '117', '--raw', '--subdir', 'DAGS_FOLDER/homework_dag.py', '--cfg-path', '/tmp/tmpnuvw_ht5']
[2024-12-06T20:32:58.416+0000] {standard_task_runner.py:105} INFO - Job 117: Subtask download_dataset
[2024-12-06T20:32:58.502+0000] {task_command.py:467} INFO - Running <TaskInstance: homework_dag.download_dataset scheduled__2021-01-05T06:00:00+00:00 [running]> on host 39ecaeffba2c
[2024-12-06T20:32:59.372+0000] {taskinstance.py:3132} INFO - Exporting env vars: AIRFLOW_CTX_DAG_OWNER='***' AIRFLOW_CTX_DAG_ID='homework_dag' AIRFLOW_CTX_TASK_ID='download_dataset' AIRFLOW_CTX_EXECUTION_DATE='2021-01-05T06:00:00+00:00' AIRFLOW_CTX_TRY_NUMBER='5' AIRFLOW_CTX_DAG_RUN_ID='scheduled__2021-01-05T06:00:00+00:00'
[2024-12-06T20:32:59.383+0000] {taskinstance.py:731} INFO - ::endgroup::
[2024-12-06T20:32:59.399+0000] {subprocess.py:78} INFO - Tmp dir root location: /tmp
[2024-12-06T20:32:59.400+0000] {subprocess.py:88} INFO - Running command: ['/usr/bin/bash', '-c', 'wget https://d37ci6vzurychx.cloudfront.net/trip-data/fhv_tripdata_2021-01.parquet -O /opt/***output_2021-01.parquet']
[2024-12-06T20:32:59.408+0000] {subprocess.py:99} INFO - Output:
[2024-12-06T20:32:59.410+0000] {subprocess.py:106} INFO - /opt/***output_2021-01.parquet: Permission denied
[2024-12-06T20:32:59.411+0000] {subprocess.py:110} INFO - Command exited with return code 1
[2024-12-06T20:32:59.420+0000] {taskinstance.py:3311} ERROR - Task failed with exception
Traceback (most recent call last):
  File "/home/airflow/.local/lib/python3.12/site-packages/airflow/models/taskinstance.py", line 767, in _execute_task
    result = _execute_callable(context=context, **execute_callable_kwargs)
             ^^^^^^^^^^^^^^^^^^^^^^^^^^^^^^^^^^^^^^^^^^^^^^^^^^^^^^^^^^^^^
  File "/home/airflow/.local/lib/python3.12/site-packages/airflow/models/taskinstance.py", line 733, in _execute_callable
    return ExecutionCallableRunner(
           ^^^^^^^^^^^^^^^^^^^^^^^^
  File "/home/airflow/.local/lib/python3.12/site-packages/airflow/utils/operator_helpers.py", line 252, in run
    return self.func(*args, **kwargs)
           ^^^^^^^^^^^^^^^^^^^^^^^^^^
  File "/home/airflow/.local/lib/python3.12/site-packages/airflow/models/baseoperator.py", line 417, in wrapper
    return func(self, *args, **kwargs)
           ^^^^^^^^^^^^^^^^^^^^^^^^^^^
  File "/home/airflow/.local/lib/python3.12/site-packages/airflow/operators/bash.py", line 276, in execute
    raise AirflowException(
airflow.exceptions.AirflowException: Bash command failed. The command returned a non-zero exit code 1.
[2024-12-06T20:32:59.423+0000] {taskinstance.py:1225} INFO - Marking task as FAILED. dag_id=homework_dag, task_id=download_dataset, run_id=scheduled__2021-01-05T06:00:00+00:00, execution_date=20210105T060000, start_date=20241206T203258, end_date=20241206T203259
[2024-12-06T20:32:59.433+0000] {taskinstance.py:340} INFO - ::group::Post task execution logs
[2024-12-06T20:32:59.433+0000] {standard_task_runner.py:124} ERROR - Failed to execute job 117 for task download_dataset (Bash command failed. The command returned a non-zero exit code 1.; 4414)
Traceback (most recent call last):
  File "/home/airflow/.local/lib/python3.12/site-packages/airflow/task/task_runner/standard_task_runner.py", line 117, in _start_by_fork
    ret = args.func(args, dag=self.dag)
          ^^^^^^^^^^^^^^^^^^^^^^^^^^^^^
  File "/home/airflow/.local/lib/python3.12/site-packages/airflow/cli/cli_config.py", line 49, in command
    return func(*args, **kwargs)
           ^^^^^^^^^^^^^^^^^^^^^
  File "/home/airflow/.local/lib/python3.12/site-packages/airflow/utils/cli.py", line 116, in wrapper
    return f(*args, **kwargs)
           ^^^^^^^^^^^^^^^^^^
  File "/home/airflow/.local/lib/python3.12/site-packages/airflow/cli/commands/task_command.py", line 483, in task_run
    task_return_code = _run_task_by_selected_method(args, _dag, ti)
                       ^^^^^^^^^^^^^^^^^^^^^^^^^^^^^^^^^^^^^^^^^^^^
  File "/home/airflow/.local/lib/python3.12/site-packages/airflow/cli/commands/task_command.py", line 256, in _run_task_by_selected_method
    return _run_raw_task(args, ti)
           ^^^^^^^^^^^^^^^^^^^^^^^
  File "/home/airflow/.local/lib/python3.12/site-packages/airflow/cli/commands/task_command.py", line 341, in _run_raw_task
    return ti._run_raw_task(
           ^^^^^^^^^^^^^^^^^
  File "/home/airflow/.local/lib/python3.12/site-packages/airflow/utils/session.py", line 97, in wrapper
    return func(*args, session=session, **kwargs)
           ^^^^^^^^^^^^^^^^^^^^^^^^^^^^^^^^^^^^^^
  File "/home/airflow/.local/lib/python3.12/site-packages/airflow/models/taskinstance.py", line 3005, in _run_raw_task
    return _run_raw_task(
           ^^^^^^^^^^^^^^
  File "/home/airflow/.local/lib/python3.12/site-packages/airflow/models/taskinstance.py", line 273, in _run_raw_task
    TaskInstance._execute_task_with_callbacks(
  File "/home/airflow/.local/lib/python3.12/site-packages/airflow/models/taskinstance.py", line 3159, in _execute_task_with_callbacks
    result = self._execute_task(context, task_orig)
             ^^^^^^^^^^^^^^^^^^^^^^^^^^^^^^^^^^^^^^
  File "/home/airflow/.local/lib/python3.12/site-packages/airflow/models/taskinstance.py", line 3183, in _execute_task
    return _execute_task(self, context, task_orig)
           ^^^^^^^^^^^^^^^^^^^^^^^^^^^^^^^^^^^^^^^
  File "/home/airflow/.local/lib/python3.12/site-packages/airflow/models/taskinstance.py", line 767, in _execute_task
    result = _execute_callable(context=context, **execute_callable_kwargs)
             ^^^^^^^^^^^^^^^^^^^^^^^^^^^^^^^^^^^^^^^^^^^^^^^^^^^^^^^^^^^^^
  File "/home/airflow/.local/lib/python3.12/site-packages/airflow/models/taskinstance.py", line 733, in _execute_callable
    return ExecutionCallableRunner(
           ^^^^^^^^^^^^^^^^^^^^^^^^
  File "/home/airflow/.local/lib/python3.12/site-packages/airflow/utils/operator_helpers.py", line 252, in run
    return self.func(*args, **kwargs)
           ^^^^^^^^^^^^^^^^^^^^^^^^^^
  File "/home/airflow/.local/lib/python3.12/site-packages/airflow/models/baseoperator.py", line 417, in wrapper
    return func(self, *args, **kwargs)
           ^^^^^^^^^^^^^^^^^^^^^^^^^^^
  File "/home/airflow/.local/lib/python3.12/site-packages/airflow/operators/bash.py", line 276, in execute
    raise AirflowException(
airflow.exceptions.AirflowException: Bash command failed. The command returned a non-zero exit code 1.
[2024-12-06T20:32:59.467+0000] {local_task_job_runner.py:266} INFO - Task exited with return code 1
[2024-12-06T20:32:59.509+0000] {taskinstance.py:3895} INFO - 0 downstream tasks scheduled from follow-on schedule check
[2024-12-06T20:32:59.514+0000] {local_task_job_runner.py:245} INFO - ::endgroup::
