[2024-11-23T01:01:08.530+0000] {local_task_job_runner.py:123} INFO - ::group::Pre task execution logs
[2024-11-23T01:01:08.539+0000] {taskinstance.py:2613} INFO - Dependencies all met for dep_context=non-requeueable deps ti=<TaskInstance: data_ingestion_gcs_dag.download_dataset_task scheduled__2024-11-22T00:00:00+00:00 [queued]>
[2024-11-23T01:01:08.543+0000] {taskinstance.py:2613} INFO - Dependencies all met for dep_context=requeueable deps ti=<TaskInstance: data_ingestion_gcs_dag.download_dataset_task scheduled__2024-11-22T00:00:00+00:00 [queued]>
[2024-11-23T01:01:08.543+0000] {taskinstance.py:2866} INFO - Starting attempt 2 of 2
[2024-11-23T01:01:08.549+0000] {taskinstance.py:2889} INFO - Executing <Task(BashOperator): download_dataset_task> on 2024-11-22 00:00:00+00:00
[2024-11-23T01:01:08.554+0000] {warnings.py:112} WARNING - /home/***/.local/lib/python3.12/site-packages/***/task/task_runner/standard_task_runner.py:70: DeprecationWarning: This process (pid=37522) is multi-threaded, use of fork() may lead to deadlocks in the child.
  pid = os.fork()

[2024-11-23T01:01:08.555+0000] {standard_task_runner.py:72} INFO - Started process 37523 to run task
[2024-11-23T01:01:08.555+0000] {standard_task_runner.py:104} INFO - Running: ['***', 'tasks', 'run', 'data_ingestion_gcs_dag', 'download_dataset_task', 'scheduled__2024-11-22T00:00:00+00:00', '--job-id', '86', '--raw', '--subdir', 'DAGS_FOLDER/data_ingestion_gcs_dag.py', '--cfg-path', '/tmp/tmp2xxw5o_j']
[2024-11-23T01:01:08.557+0000] {standard_task_runner.py:105} INFO - Job 86: Subtask download_dataset_task
[2024-11-23T01:01:08.580+0000] {task_command.py:467} INFO - Running <TaskInstance: data_ingestion_gcs_dag.download_dataset_task scheduled__2024-11-22T00:00:00+00:00 [running]> on host 4cef807186dc
[2024-11-23T01:01:08.611+0000] {taskinstance.py:3132} INFO - Exporting env vars: AIRFLOW_CTX_DAG_OWNER='***' AIRFLOW_CTX_DAG_ID='data_ingestion_gcs_dag' AIRFLOW_CTX_TASK_ID='download_dataset_task' AIRFLOW_CTX_EXECUTION_DATE='2024-11-22T00:00:00+00:00' AIRFLOW_CTX_TRY_NUMBER='2' AIRFLOW_CTX_DAG_RUN_ID='scheduled__2024-11-22T00:00:00+00:00'
[2024-11-23T01:01:08.611+0000] {taskinstance.py:731} INFO - ::endgroup::
[2024-11-23T01:01:08.618+0000] {subprocess.py:78} INFO - Tmp dir root location: /tmp
[2024-11-23T01:01:08.618+0000] {subprocess.py:88} INFO - Running command: ['/usr/bin/bash', '-c', 'curl -sSL https://s3.amazonaws.com/nyc-tlc/trip+data/yellow_tripdata_2021-01.csv > /opt/***/yellow_tripdata_2021-01.csv']
[2024-11-23T01:01:08.624+0000] {subprocess.py:99} INFO - Output:
[2024-11-23T01:01:08.642+0000] {subprocess.py:106} INFO - curl: (6) Could not resolve host: s3.amazonaws.com
[2024-11-23T01:01:08.643+0000] {subprocess.py:110} INFO - Command exited with return code 6
[2024-11-23T01:01:08.649+0000] {taskinstance.py:3311} ERROR - Task failed with exception
Traceback (most recent call last):
  File "/home/airflow/.local/lib/python3.12/site-packages/airflow/models/taskinstance.py", line 767, in _execute_task
    result = _execute_callable(context=context, **execute_callable_kwargs)
             ^^^^^^^^^^^^^^^^^^^^^^^^^^^^^^^^^^^^^^^^^^^^^^^^^^^^^^^^^^^^^
  File "/home/airflow/.local/lib/python3.12/site-packages/airflow/models/taskinstance.py", line 733, in _execute_callable
    return ExecutionCallableRunner(
           ^^^^^^^^^^^^^^^^^^^^^^^^
  File "/home/airflow/.local/lib/python3.12/site-packages/airflow/utils/operator_helpers.py", line 252, in run
    return self.func(*args, **kwargs)
           ^^^^^^^^^^^^^^^^^^^^^^^^^^
  File "/home/airflow/.local/lib/python3.12/site-packages/airflow/models/baseoperator.py", line 417, in wrapper
    return func(self, *args, **kwargs)
           ^^^^^^^^^^^^^^^^^^^^^^^^^^^
  File "/home/airflow/.local/lib/python3.12/site-packages/airflow/operators/bash.py", line 276, in execute
    raise AirflowException(
airflow.exceptions.AirflowException: Bash command failed. The command returned a non-zero exit code 6.
[2024-11-23T01:01:08.651+0000] {taskinstance.py:1225} INFO - Marking task as FAILED. dag_id=data_ingestion_gcs_dag, task_id=download_dataset_task, run_id=scheduled__2024-11-22T00:00:00+00:00, execution_date=20241122T000000, start_date=20241123T010108, end_date=20241123T010108
[2024-11-23T01:01:08.657+0000] {taskinstance.py:340} INFO - ::group::Post task execution logs
[2024-11-23T01:01:08.657+0000] {standard_task_runner.py:124} ERROR - Failed to execute job 86 for task download_dataset_task (Bash command failed. The command returned a non-zero exit code 6.; 37523)
Traceback (most recent call last):
  File "/home/airflow/.local/lib/python3.12/site-packages/airflow/task/task_runner/standard_task_runner.py", line 117, in _start_by_fork
    ret = args.func(args, dag=self.dag)
          ^^^^^^^^^^^^^^^^^^^^^^^^^^^^^
  File "/home/airflow/.local/lib/python3.12/site-packages/airflow/cli/cli_config.py", line 49, in command
    return func(*args, **kwargs)
           ^^^^^^^^^^^^^^^^^^^^^
  File "/home/airflow/.local/lib/python3.12/site-packages/airflow/utils/cli.py", line 116, in wrapper
    return f(*args, **kwargs)
           ^^^^^^^^^^^^^^^^^^
  File "/home/airflow/.local/lib/python3.12/site-packages/airflow/cli/commands/task_command.py", line 483, in task_run
    task_return_code = _run_task_by_selected_method(args, _dag, ti)
                       ^^^^^^^^^^^^^^^^^^^^^^^^^^^^^^^^^^^^^^^^^^^^
  File "/home/airflow/.local/lib/python3.12/site-packages/airflow/cli/commands/task_command.py", line 256, in _run_task_by_selected_method
    return _run_raw_task(args, ti)
           ^^^^^^^^^^^^^^^^^^^^^^^
  File "/home/airflow/.local/lib/python3.12/site-packages/airflow/cli/commands/task_command.py", line 341, in _run_raw_task
    return ti._run_raw_task(
           ^^^^^^^^^^^^^^^^^
  File "/home/airflow/.local/lib/python3.12/site-packages/airflow/utils/session.py", line 97, in wrapper
    return func(*args, session=session, **kwargs)
           ^^^^^^^^^^^^^^^^^^^^^^^^^^^^^^^^^^^^^^
  File "/home/airflow/.local/lib/python3.12/site-packages/airflow/models/taskinstance.py", line 3005, in _run_raw_task
    return _run_raw_task(
           ^^^^^^^^^^^^^^
  File "/home/airflow/.local/lib/python3.12/site-packages/airflow/models/taskinstance.py", line 273, in _run_raw_task
    TaskInstance._execute_task_with_callbacks(
  File "/home/airflow/.local/lib/python3.12/site-packages/airflow/models/taskinstance.py", line 3159, in _execute_task_with_callbacks
    result = self._execute_task(context, task_orig)
             ^^^^^^^^^^^^^^^^^^^^^^^^^^^^^^^^^^^^^^
  File "/home/airflow/.local/lib/python3.12/site-packages/airflow/models/taskinstance.py", line 3183, in _execute_task
    return _execute_task(self, context, task_orig)
           ^^^^^^^^^^^^^^^^^^^^^^^^^^^^^^^^^^^^^^^
  File "/home/airflow/.local/lib/python3.12/site-packages/airflow/models/taskinstance.py", line 767, in _execute_task
    result = _execute_callable(context=context, **execute_callable_kwargs)
             ^^^^^^^^^^^^^^^^^^^^^^^^^^^^^^^^^^^^^^^^^^^^^^^^^^^^^^^^^^^^^
  File "/home/airflow/.local/lib/python3.12/site-packages/airflow/models/taskinstance.py", line 733, in _execute_callable
    return ExecutionCallableRunner(
           ^^^^^^^^^^^^^^^^^^^^^^^^
  File "/home/airflow/.local/lib/python3.12/site-packages/airflow/utils/operator_helpers.py", line 252, in run
    return self.func(*args, **kwargs)
           ^^^^^^^^^^^^^^^^^^^^^^^^^^
  File "/home/airflow/.local/lib/python3.12/site-packages/airflow/models/baseoperator.py", line 417, in wrapper
    return func(self, *args, **kwargs)
           ^^^^^^^^^^^^^^^^^^^^^^^^^^^
  File "/home/airflow/.local/lib/python3.12/site-packages/airflow/operators/bash.py", line 276, in execute
    raise AirflowException(
airflow.exceptions.AirflowException: Bash command failed. The command returned a non-zero exit code 6.
[2024-11-23T01:01:08.704+0000] {local_task_job_runner.py:266} INFO - Task exited with return code 1
[2024-11-23T01:01:08.715+0000] {taskinstance.py:3895} INFO - 0 downstream tasks scheduled from follow-on schedule check
[2024-11-23T01:01:08.717+0000] {local_task_job_runner.py:245} INFO - ::endgroup::
