[2024-11-15T17:18:43.873+0000] {local_task_job_runner.py:123} INFO - ::group::Pre task execution logs
[2024-11-15T17:18:43.884+0000] {taskinstance.py:2613} INFO - Dependencies all met for dep_context=non-requeueable deps ti=<TaskInstance: data_ingestion_gcs_dag.local_to_gcs_task manual__2024-11-15T17:18:37.452676+00:00 [queued]>
[2024-11-15T17:18:43.890+0000] {taskinstance.py:2613} INFO - Dependencies all met for dep_context=requeueable deps ti=<TaskInstance: data_ingestion_gcs_dag.local_to_gcs_task manual__2024-11-15T17:18:37.452676+00:00 [queued]>
[2024-11-15T17:18:43.891+0000] {taskinstance.py:2866} INFO - Starting attempt 1 of 2
[2024-11-15T17:18:43.897+0000] {taskinstance.py:2889} INFO - Executing <Task(PythonOperator): local_to_gcs_task> on 2024-11-15 17:18:37.452676+00:00
[2024-11-15T17:18:43.902+0000] {warnings.py:112} WARNING - /home/***/.local/lib/python3.12/site-packages/***/task/task_runner/standard_task_runner.py:70: DeprecationWarning: This process (pid=139) is multi-threaded, use of fork() may lead to deadlocks in the child.
  pid = os.fork()

[2024-11-15T17:18:43.903+0000] {standard_task_runner.py:72} INFO - Started process 140 to run task
[2024-11-15T17:18:43.903+0000] {standard_task_runner.py:104} INFO - Running: ['***', 'tasks', 'run', 'data_ingestion_gcs_dag', 'local_to_gcs_task', 'manual__2024-11-15T17:18:37.452676+00:00', '--job-id', '22', '--raw', '--subdir', 'DAGS_FOLDER/fds.py', '--cfg-path', '/tmp/tmpva3irk76']
[2024-11-15T17:18:43.905+0000] {standard_task_runner.py:105} INFO - Job 22: Subtask local_to_gcs_task
[2024-11-15T17:18:43.929+0000] {task_command.py:467} INFO - Running <TaskInstance: data_ingestion_gcs_dag.local_to_gcs_task manual__2024-11-15T17:18:37.452676+00:00 [running]> on host 5a707e3d7d2e
[2024-11-15T17:18:43.971+0000] {taskinstance.py:3132} INFO - Exporting env vars: AIRFLOW_CTX_DAG_OWNER='***' AIRFLOW_CTX_DAG_ID='data_ingestion_gcs_dag' AIRFLOW_CTX_TASK_ID='local_to_gcs_task' AIRFLOW_CTX_EXECUTION_DATE='2024-11-15T17:18:37.452676+00:00' AIRFLOW_CTX_TRY_NUMBER='1' AIRFLOW_CTX_DAG_RUN_ID='manual__2024-11-15T17:18:37.452676+00:00'
[2024-11-15T17:18:43.972+0000] {taskinstance.py:731} INFO - ::endgroup::
[2024-11-15T17:18:43.979+0000] {taskinstance.py:3311} ERROR - Task failed with exception
Traceback (most recent call last):
  File "/home/airflow/.local/lib/python3.12/site-packages/airflow/models/taskinstance.py", line 767, in _execute_task
    result = _execute_callable(context=context, **execute_callable_kwargs)
             ^^^^^^^^^^^^^^^^^^^^^^^^^^^^^^^^^^^^^^^^^^^^^^^^^^^^^^^^^^^^^
  File "/home/airflow/.local/lib/python3.12/site-packages/airflow/models/taskinstance.py", line 733, in _execute_callable
    return ExecutionCallableRunner(
           ^^^^^^^^^^^^^^^^^^^^^^^^
  File "/home/airflow/.local/lib/python3.12/site-packages/airflow/utils/operator_helpers.py", line 252, in run
    return self.func(*args, **kwargs)
           ^^^^^^^^^^^^^^^^^^^^^^^^^^
  File "/home/airflow/.local/lib/python3.12/site-packages/airflow/models/baseoperator.py", line 417, in wrapper
    return func(self, *args, **kwargs)
           ^^^^^^^^^^^^^^^^^^^^^^^^^^^
  File "/home/airflow/.local/lib/python3.12/site-packages/airflow/operators/python.py", line 238, in execute
    return_value = self.execute_callable()
                   ^^^^^^^^^^^^^^^^^^^^^^^
  File "/home/airflow/.local/lib/python3.12/site-packages/airflow/operators/python.py", line 256, in execute_callable
    return runner.run(*self.op_args, **self.op_kwargs)
           ^^^^^^^^^^^^^^^^^^^^^^^^^^^^^^^^^^^^^^^^^^^
  File "/home/airflow/.local/lib/python3.12/site-packages/airflow/utils/operator_helpers.py", line 252, in run
    return self.func(*args, **kwargs)
           ^^^^^^^^^^^^^^^^^^^^^^^^^^
  File "/opt/airflow/dags/fds.py", line 47, in upload_to_gcs
    client = storage.Client()
             ^^^^^^^^^^^^^^^^
  File "/home/airflow/.local/lib/python3.12/site-packages/google/cloud/storage/client.py", line 227, in __init__
    super(Client, self).__init__(
  File "/home/airflow/.local/lib/python3.12/site-packages/google/cloud/client/__init__.py", line 320, in __init__
    _ClientProjectMixin.__init__(self, project=project, credentials=credentials)
  File "/home/airflow/.local/lib/python3.12/site-packages/google/cloud/client/__init__.py", line 268, in __init__
    project = self._determine_default(project)
              ^^^^^^^^^^^^^^^^^^^^^^^^^^^^^^^^
  File "/home/airflow/.local/lib/python3.12/site-packages/google/cloud/client/__init__.py", line 287, in _determine_default
    return _determine_default_project(project)
           ^^^^^^^^^^^^^^^^^^^^^^^^^^^^^^^^^^^
  File "/home/airflow/.local/lib/python3.12/site-packages/google/cloud/_helpers/__init__.py", line 152, in _determine_default_project
    _, project = google.auth.default()
                 ^^^^^^^^^^^^^^^^^^^^^
  File "/home/airflow/.local/lib/python3.12/site-packages/google/auth/_default.py", line 659, in default
    credentials, project_id = checker()
                              ^^^^^^^^^
  File "/home/airflow/.local/lib/python3.12/site-packages/google/auth/_default.py", line 652, in <lambda>
    lambda: _get_explicit_environ_credentials(quota_project_id=quota_project_id),
            ^^^^^^^^^^^^^^^^^^^^^^^^^^^^^^^^^^^^^^^^^^^^^^^^^^^^^^^^^^^^^^^^^^^^
  File "/home/airflow/.local/lib/python3.12/site-packages/google/auth/_default.py", line 271, in _get_explicit_environ_credentials
    credentials, project_id = load_credentials_from_file(
                              ^^^^^^^^^^^^^^^^^^^^^^^^^^^
  File "/home/airflow/.local/lib/python3.12/site-packages/google/auth/_default.py", line 114, in load_credentials_from_file
    raise exceptions.DefaultCredentialsError(
google.auth.exceptions.DefaultCredentialsError: File /.google/credentials/google_credentials.json was not found.
[2024-11-15T17:18:43.987+0000] {taskinstance.py:1225} INFO - Marking task as UP_FOR_RETRY. dag_id=data_ingestion_gcs_dag, task_id=local_to_gcs_task, run_id=manual__2024-11-15T17:18:37.452676+00:00, execution_date=20241115T171837, start_date=20241115T171843, end_date=20241115T171843
[2024-11-15T17:18:43.997+0000] {taskinstance.py:340} INFO - ::group::Post task execution logs
[2024-11-15T17:18:43.997+0000] {standard_task_runner.py:124} ERROR - Failed to execute job 22 for task local_to_gcs_task (File /.google/credentials/google_credentials.json was not found.; 140)
Traceback (most recent call last):
  File "/home/airflow/.local/lib/python3.12/site-packages/airflow/task/task_runner/standard_task_runner.py", line 117, in _start_by_fork
    ret = args.func(args, dag=self.dag)
          ^^^^^^^^^^^^^^^^^^^^^^^^^^^^^
  File "/home/airflow/.local/lib/python3.12/site-packages/airflow/cli/cli_config.py", line 49, in command
    return func(*args, **kwargs)
           ^^^^^^^^^^^^^^^^^^^^^
  File "/home/airflow/.local/lib/python3.12/site-packages/airflow/utils/cli.py", line 116, in wrapper
    return f(*args, **kwargs)
           ^^^^^^^^^^^^^^^^^^
  File "/home/airflow/.local/lib/python3.12/site-packages/airflow/cli/commands/task_command.py", line 483, in task_run
    task_return_code = _run_task_by_selected_method(args, _dag, ti)
                       ^^^^^^^^^^^^^^^^^^^^^^^^^^^^^^^^^^^^^^^^^^^^
  File "/home/airflow/.local/lib/python3.12/site-packages/airflow/cli/commands/task_command.py", line 256, in _run_task_by_selected_method
    return _run_raw_task(args, ti)
           ^^^^^^^^^^^^^^^^^^^^^^^
  File "/home/airflow/.local/lib/python3.12/site-packages/airflow/cli/commands/task_command.py", line 341, in _run_raw_task
    return ti._run_raw_task(
           ^^^^^^^^^^^^^^^^^
  File "/home/airflow/.local/lib/python3.12/site-packages/airflow/utils/session.py", line 97, in wrapper
    return func(*args, session=session, **kwargs)
           ^^^^^^^^^^^^^^^^^^^^^^^^^^^^^^^^^^^^^^
  File "/home/airflow/.local/lib/python3.12/site-packages/airflow/models/taskinstance.py", line 3005, in _run_raw_task
    return _run_raw_task(
           ^^^^^^^^^^^^^^
  File "/home/airflow/.local/lib/python3.12/site-packages/airflow/models/taskinstance.py", line 273, in _run_raw_task
    TaskInstance._execute_task_with_callbacks(
  File "/home/airflow/.local/lib/python3.12/site-packages/airflow/models/taskinstance.py", line 3159, in _execute_task_with_callbacks
    result = self._execute_task(context, task_orig)
             ^^^^^^^^^^^^^^^^^^^^^^^^^^^^^^^^^^^^^^
  File "/home/airflow/.local/lib/python3.12/site-packages/airflow/models/taskinstance.py", line 3183, in _execute_task
    return _execute_task(self, context, task_orig)
           ^^^^^^^^^^^^^^^^^^^^^^^^^^^^^^^^^^^^^^^
  File "/home/airflow/.local/lib/python3.12/site-packages/airflow/models/taskinstance.py", line 767, in _execute_task
    result = _execute_callable(context=context, **execute_callable_kwargs)
             ^^^^^^^^^^^^^^^^^^^^^^^^^^^^^^^^^^^^^^^^^^^^^^^^^^^^^^^^^^^^^
  File "/home/airflow/.local/lib/python3.12/site-packages/airflow/models/taskinstance.py", line 733, in _execute_callable
    return ExecutionCallableRunner(
           ^^^^^^^^^^^^^^^^^^^^^^^^
  File "/home/airflow/.local/lib/python3.12/site-packages/airflow/utils/operator_helpers.py", line 252, in run
    return self.func(*args, **kwargs)
           ^^^^^^^^^^^^^^^^^^^^^^^^^^
  File "/home/airflow/.local/lib/python3.12/site-packages/airflow/models/baseoperator.py", line 417, in wrapper
    return func(self, *args, **kwargs)
           ^^^^^^^^^^^^^^^^^^^^^^^^^^^
  File "/home/airflow/.local/lib/python3.12/site-packages/airflow/operators/python.py", line 238, in execute
    return_value = self.execute_callable()
                   ^^^^^^^^^^^^^^^^^^^^^^^
  File "/home/airflow/.local/lib/python3.12/site-packages/airflow/operators/python.py", line 256, in execute_callable
    return runner.run(*self.op_args, **self.op_kwargs)
           ^^^^^^^^^^^^^^^^^^^^^^^^^^^^^^^^^^^^^^^^^^^
  File "/home/airflow/.local/lib/python3.12/site-packages/airflow/utils/operator_helpers.py", line 252, in run
    return self.func(*args, **kwargs)
           ^^^^^^^^^^^^^^^^^^^^^^^^^^
  File "/opt/airflow/dags/fds.py", line 47, in upload_to_gcs
    client = storage.Client()
             ^^^^^^^^^^^^^^^^
  File "/home/airflow/.local/lib/python3.12/site-packages/google/cloud/storage/client.py", line 227, in __init__
    super(Client, self).__init__(
  File "/home/airflow/.local/lib/python3.12/site-packages/google/cloud/client/__init__.py", line 320, in __init__
    _ClientProjectMixin.__init__(self, project=project, credentials=credentials)
  File "/home/airflow/.local/lib/python3.12/site-packages/google/cloud/client/__init__.py", line 268, in __init__
    project = self._determine_default(project)
              ^^^^^^^^^^^^^^^^^^^^^^^^^^^^^^^^
  File "/home/airflow/.local/lib/python3.12/site-packages/google/cloud/client/__init__.py", line 287, in _determine_default
    return _determine_default_project(project)
           ^^^^^^^^^^^^^^^^^^^^^^^^^^^^^^^^^^^
  File "/home/airflow/.local/lib/python3.12/site-packages/google/cloud/_helpers/__init__.py", line 152, in _determine_default_project
    _, project = google.auth.default()
                 ^^^^^^^^^^^^^^^^^^^^^
  File "/home/airflow/.local/lib/python3.12/site-packages/google/auth/_default.py", line 659, in default
    credentials, project_id = checker()
                              ^^^^^^^^^
  File "/home/airflow/.local/lib/python3.12/site-packages/google/auth/_default.py", line 652, in <lambda>
    lambda: _get_explicit_environ_credentials(quota_project_id=quota_project_id),
            ^^^^^^^^^^^^^^^^^^^^^^^^^^^^^^^^^^^^^^^^^^^^^^^^^^^^^^^^^^^^^^^^^^^^
  File "/home/airflow/.local/lib/python3.12/site-packages/google/auth/_default.py", line 271, in _get_explicit_environ_credentials
    credentials, project_id = load_credentials_from_file(
                              ^^^^^^^^^^^^^^^^^^^^^^^^^^^
  File "/home/airflow/.local/lib/python3.12/site-packages/google/auth/_default.py", line 114, in load_credentials_from_file
    raise exceptions.DefaultCredentialsError(
google.auth.exceptions.DefaultCredentialsError: File /.google/credentials/google_credentials.json was not found.
[2024-11-15T17:18:44.003+0000] {local_task_job_runner.py:266} INFO - Task exited with return code 1
[2024-11-15T17:18:44.015+0000] {taskinstance.py:3895} INFO - 0 downstream tasks scheduled from follow-on schedule check
[2024-11-15T17:18:44.016+0000] {local_task_job_runner.py:245} INFO - ::endgroup::
