[2024-12-05T18:08:46.369+0000] {local_task_job_runner.py:123} INFO - ::group::Pre task execution logs
[2024-12-05T18:08:46.401+0000] {taskinstance.py:2613} INFO - Dependencies all met for dep_context=non-requeueable deps ti=<TaskInstance: LocalIngestionDag.ingest scheduled__2022-05-02T06:00:00+00:00 [queued]>
[2024-12-05T18:08:46.412+0000] {taskinstance.py:2613} INFO - Dependencies all met for dep_context=requeueable deps ti=<TaskInstance: LocalIngestionDag.ingest scheduled__2022-05-02T06:00:00+00:00 [queued]>
[2024-12-05T18:08:46.413+0000] {taskinstance.py:2866} INFO - Starting attempt 1 of 1
[2024-12-05T18:08:46.433+0000] {taskinstance.py:2889} INFO - Executing <Task(BashOperator): ingest> on 2022-05-02 06:00:00+00:00
[2024-12-05T18:08:46.437+0000] {warnings.py:112} WARNING - /home/***/.local/lib/python3.12/site-packages/***/task/task_runner/standard_task_runner.py:70: DeprecationWarning: This process (pid=1690) is multi-threaded, use of fork() may lead to deadlocks in the child.
  pid = os.fork()

[2024-12-05T18:08:46.439+0000] {standard_task_runner.py:72} INFO - Started process 1709 to run task
[2024-12-05T18:08:46.439+0000] {standard_task_runner.py:104} INFO - Running: ['***', 'tasks', 'run', 'LocalIngestionDag', 'ingest', 'scheduled__2022-05-02T06:00:00+00:00', '--job-id', '201', '--raw', '--subdir', 'DAGS_FOLDER/data_ingestion_local.py', '--cfg-path', '/tmp/tmp31rz52r3']
[2024-12-05T18:08:46.445+0000] {standard_task_runner.py:105} INFO - Job 201: Subtask ingest
[2024-12-05T18:08:46.569+0000] {task_command.py:467} INFO - Running <TaskInstance: LocalIngestionDag.ingest scheduled__2022-05-02T06:00:00+00:00 [running]> on host 073dea24e113
[2024-12-05T18:08:46.661+0000] {taskinstance.py:3132} INFO - Exporting env vars: AIRFLOW_CTX_DAG_OWNER='***' AIRFLOW_CTX_DAG_ID='LocalIngestionDag' AIRFLOW_CTX_TASK_ID='ingest' AIRFLOW_CTX_EXECUTION_DATE='2022-05-02T06:00:00+00:00' AIRFLOW_CTX_TRY_NUMBER='1' AIRFLOW_CTX_DAG_RUN_ID='scheduled__2022-05-02T06:00:00+00:00'
[2024-12-05T18:08:46.669+0000] {taskinstance.py:731} INFO - ::endgroup::
[2024-12-05T18:08:46.680+0000] {subprocess.py:78} INFO - Tmp dir root location: /tmp
[2024-12-05T18:08:46.682+0000] {subprocess.py:88} INFO - Running command: ['/usr/bin/bash', '-c', 'pwd"']
[2024-12-05T18:08:46.697+0000] {subprocess.py:99} INFO - Output:
[2024-12-05T18:08:46.699+0000] {subprocess.py:106} INFO - /usr/bin/bash: -c: line 1: unexpected EOF while looking for matching `"'
[2024-12-05T18:08:46.700+0000] {subprocess.py:110} INFO - Command exited with return code 2
[2024-12-05T18:08:46.713+0000] {taskinstance.py:3311} ERROR - Task failed with exception
Traceback (most recent call last):
  File "/home/airflow/.local/lib/python3.12/site-packages/airflow/models/taskinstance.py", line 767, in _execute_task
    result = _execute_callable(context=context, **execute_callable_kwargs)
             ^^^^^^^^^^^^^^^^^^^^^^^^^^^^^^^^^^^^^^^^^^^^^^^^^^^^^^^^^^^^^
  File "/home/airflow/.local/lib/python3.12/site-packages/airflow/models/taskinstance.py", line 733, in _execute_callable
    return ExecutionCallableRunner(
           ^^^^^^^^^^^^^^^^^^^^^^^^
  File "/home/airflow/.local/lib/python3.12/site-packages/airflow/utils/operator_helpers.py", line 252, in run
    return self.func(*args, **kwargs)
           ^^^^^^^^^^^^^^^^^^^^^^^^^^
  File "/home/airflow/.local/lib/python3.12/site-packages/airflow/models/baseoperator.py", line 417, in wrapper
    return func(self, *args, **kwargs)
           ^^^^^^^^^^^^^^^^^^^^^^^^^^^
  File "/home/airflow/.local/lib/python3.12/site-packages/airflow/operators/bash.py", line 276, in execute
    raise AirflowException(
airflow.exceptions.AirflowException: Bash command failed. The command returned a non-zero exit code 2.
[2024-12-05T18:08:46.725+0000] {taskinstance.py:1225} INFO - Marking task as FAILED. dag_id=LocalIngestionDag, task_id=ingest, run_id=scheduled__2022-05-02T06:00:00+00:00, execution_date=20220502T060000, start_date=20241205T180846, end_date=20241205T180846
[2024-12-05T18:08:46.769+0000] {taskinstance.py:340} INFO - ::group::Post task execution logs
[2024-12-05T18:08:46.774+0000] {standard_task_runner.py:124} ERROR - Failed to execute job 201 for task ingest (Bash command failed. The command returned a non-zero exit code 2.; 1709)
Traceback (most recent call last):
  File "/home/airflow/.local/lib/python3.12/site-packages/airflow/task/task_runner/standard_task_runner.py", line 117, in _start_by_fork
    ret = args.func(args, dag=self.dag)
          ^^^^^^^^^^^^^^^^^^^^^^^^^^^^^
  File "/home/airflow/.local/lib/python3.12/site-packages/airflow/cli/cli_config.py", line 49, in command
    return func(*args, **kwargs)
           ^^^^^^^^^^^^^^^^^^^^^
  File "/home/airflow/.local/lib/python3.12/site-packages/airflow/utils/cli.py", line 116, in wrapper
    return f(*args, **kwargs)
           ^^^^^^^^^^^^^^^^^^
  File "/home/airflow/.local/lib/python3.12/site-packages/airflow/cli/commands/task_command.py", line 483, in task_run
    task_return_code = _run_task_by_selected_method(args, _dag, ti)
                       ^^^^^^^^^^^^^^^^^^^^^^^^^^^^^^^^^^^^^^^^^^^^
  File "/home/airflow/.local/lib/python3.12/site-packages/airflow/cli/commands/task_command.py", line 256, in _run_task_by_selected_method
    return _run_raw_task(args, ti)
           ^^^^^^^^^^^^^^^^^^^^^^^
  File "/home/airflow/.local/lib/python3.12/site-packages/airflow/cli/commands/task_command.py", line 341, in _run_raw_task
    return ti._run_raw_task(
           ^^^^^^^^^^^^^^^^^
  File "/home/airflow/.local/lib/python3.12/site-packages/airflow/utils/session.py", line 97, in wrapper
    return func(*args, session=session, **kwargs)
           ^^^^^^^^^^^^^^^^^^^^^^^^^^^^^^^^^^^^^^
  File "/home/airflow/.local/lib/python3.12/site-packages/airflow/models/taskinstance.py", line 3005, in _run_raw_task
    return _run_raw_task(
           ^^^^^^^^^^^^^^
  File "/home/airflow/.local/lib/python3.12/site-packages/airflow/models/taskinstance.py", line 273, in _run_raw_task
    TaskInstance._execute_task_with_callbacks(
  File "/home/airflow/.local/lib/python3.12/site-packages/airflow/models/taskinstance.py", line 3159, in _execute_task_with_callbacks
    result = self._execute_task(context, task_orig)
             ^^^^^^^^^^^^^^^^^^^^^^^^^^^^^^^^^^^^^^
  File "/home/airflow/.local/lib/python3.12/site-packages/airflow/models/taskinstance.py", line 3183, in _execute_task
    return _execute_task(self, context, task_orig)
           ^^^^^^^^^^^^^^^^^^^^^^^^^^^^^^^^^^^^^^^
  File "/home/airflow/.local/lib/python3.12/site-packages/airflow/models/taskinstance.py", line 767, in _execute_task
    result = _execute_callable(context=context, **execute_callable_kwargs)
             ^^^^^^^^^^^^^^^^^^^^^^^^^^^^^^^^^^^^^^^^^^^^^^^^^^^^^^^^^^^^^
  File "/home/airflow/.local/lib/python3.12/site-packages/airflow/models/taskinstance.py", line 733, in _execute_callable
    return ExecutionCallableRunner(
           ^^^^^^^^^^^^^^^^^^^^^^^^
  File "/home/airflow/.local/lib/python3.12/site-packages/airflow/utils/operator_helpers.py", line 252, in run
    return self.func(*args, **kwargs)
           ^^^^^^^^^^^^^^^^^^^^^^^^^^
  File "/home/airflow/.local/lib/python3.12/site-packages/airflow/models/baseoperator.py", line 417, in wrapper
    return func(self, *args, **kwargs)
           ^^^^^^^^^^^^^^^^^^^^^^^^^^^
  File "/home/airflow/.local/lib/python3.12/site-packages/airflow/operators/bash.py", line 276, in execute
    raise AirflowException(
airflow.exceptions.AirflowException: Bash command failed. The command returned a non-zero exit code 2.
[2024-12-05T18:08:46.813+0000] {local_task_job_runner.py:266} INFO - Task exited with return code 1
[2024-12-05T18:08:46.823+0000] {local_task_job_runner.py:245} INFO - ::endgroup::
