[2024-12-05T19:48:14.569+0000] {local_task_job_runner.py:123} INFO - ::group::Pre task execution logs
[2024-12-05T19:48:14.578+0000] {taskinstance.py:2613} INFO - Dependencies all met for dep_context=non-requeueable deps ti=<TaskInstance: LocalIngestionDag.wget manual__2024-12-05T19:48:12.334781+00:00 [queued]>
[2024-12-05T19:48:14.584+0000] {taskinstance.py:2613} INFO - Dependencies all met for dep_context=requeueable deps ti=<TaskInstance: LocalIngestionDag.wget manual__2024-12-05T19:48:12.334781+00:00 [queued]>
[2024-12-05T19:48:14.584+0000] {taskinstance.py:2866} INFO - Starting attempt 1 of 1
[2024-12-05T19:48:14.592+0000] {taskinstance.py:2889} INFO - Executing <Task(BashOperator): wget> on 2024-12-05 19:48:12.334781+00:00
[2024-12-05T19:48:14.596+0000] {warnings.py:112} WARNING - /home/***/.local/lib/python3.12/site-packages/***/task/task_runner/standard_task_runner.py:70: DeprecationWarning: This process (pid=68) is multi-threaded, use of fork() may lead to deadlocks in the child.
  pid = os.fork()

[2024-12-05T19:48:14.598+0000] {standard_task_runner.py:72} INFO - Started process 69 to run task
[2024-12-05T19:48:14.598+0000] {standard_task_runner.py:104} INFO - Running: ['***', 'tasks', 'run', 'LocalIngestionDag', 'wget', 'manual__2024-12-05T19:48:12.334781+00:00', '--job-id', '3', '--raw', '--subdir', 'DAGS_FOLDER/data_ingestion_local.py', '--cfg-path', '/tmp/tmp595_e_ct']
[2024-12-05T19:48:14.599+0000] {standard_task_runner.py:105} INFO - Job 3: Subtask wget
[2024-12-05T19:48:14.628+0000] {task_command.py:467} INFO - Running <TaskInstance: LocalIngestionDag.wget manual__2024-12-05T19:48:12.334781+00:00 [running]> on host 5e4fa1d24f13
[2024-12-05T19:48:14.678+0000] {taskinstance.py:3132} INFO - Exporting env vars: AIRFLOW_CTX_DAG_OWNER='***' AIRFLOW_CTX_DAG_ID='LocalIngestionDag' AIRFLOW_CTX_TASK_ID='wget' AIRFLOW_CTX_EXECUTION_DATE='2024-12-05T19:48:12.334781+00:00' AIRFLOW_CTX_TRY_NUMBER='1' AIRFLOW_CTX_DAG_RUN_ID='manual__2024-12-05T19:48:12.334781+00:00'
[2024-12-05T19:48:14.679+0000] {taskinstance.py:731} INFO - ::endgroup::
[2024-12-05T19:48:14.715+0000] {subprocess.py:78} INFO - Tmp dir root location: /tmp
[2024-12-05T19:48:14.716+0000] {subprocess.py:88} INFO - Running command: ['/usr/bin/bash', '-c', 'wget https://d37ci6vzurychx.cloudfront.net/trip-data/yellow_tripdata_2021-01.parquet -O /opt/***/output.parquet']
[2024-12-05T19:48:14.724+0000] {subprocess.py:99} INFO - Output:
[2024-12-05T19:48:14.727+0000] {subprocess.py:106} INFO - /usr/bin/bash: line 1: wget: command not found
[2024-12-05T19:48:14.728+0000] {subprocess.py:110} INFO - Command exited with return code 127
[2024-12-05T19:48:14.741+0000] {taskinstance.py:3311} ERROR - Task failed with exception
Traceback (most recent call last):
  File "/home/airflow/.local/lib/python3.12/site-packages/airflow/models/taskinstance.py", line 767, in _execute_task
    result = _execute_callable(context=context, **execute_callable_kwargs)
             ^^^^^^^^^^^^^^^^^^^^^^^^^^^^^^^^^^^^^^^^^^^^^^^^^^^^^^^^^^^^^
  File "/home/airflow/.local/lib/python3.12/site-packages/airflow/models/taskinstance.py", line 733, in _execute_callable
    return ExecutionCallableRunner(
           ^^^^^^^^^^^^^^^^^^^^^^^^
  File "/home/airflow/.local/lib/python3.12/site-packages/airflow/utils/operator_helpers.py", line 252, in run
    return self.func(*args, **kwargs)
           ^^^^^^^^^^^^^^^^^^^^^^^^^^
  File "/home/airflow/.local/lib/python3.12/site-packages/airflow/models/baseoperator.py", line 417, in wrapper
    return func(self, *args, **kwargs)
           ^^^^^^^^^^^^^^^^^^^^^^^^^^^
  File "/home/airflow/.local/lib/python3.12/site-packages/airflow/operators/bash.py", line 276, in execute
    raise AirflowException(
airflow.exceptions.AirflowException: Bash command failed. The command returned a non-zero exit code 127.
[2024-12-05T19:48:14.745+0000] {taskinstance.py:1225} INFO - Marking task as FAILED. dag_id=LocalIngestionDag, task_id=wget, run_id=manual__2024-12-05T19:48:12.334781+00:00, execution_date=20241205T194812, start_date=20241205T194814, end_date=20241205T194814
[2024-12-05T19:48:14.758+0000] {taskinstance.py:340} INFO - ::group::Post task execution logs
[2024-12-05T19:48:14.759+0000] {standard_task_runner.py:124} ERROR - Failed to execute job 3 for task wget (Bash command failed. The command returned a non-zero exit code 127.; 69)
Traceback (most recent call last):
  File "/home/airflow/.local/lib/python3.12/site-packages/airflow/task/task_runner/standard_task_runner.py", line 117, in _start_by_fork
    ret = args.func(args, dag=self.dag)
          ^^^^^^^^^^^^^^^^^^^^^^^^^^^^^
  File "/home/airflow/.local/lib/python3.12/site-packages/airflow/cli/cli_config.py", line 49, in command
    return func(*args, **kwargs)
           ^^^^^^^^^^^^^^^^^^^^^
  File "/home/airflow/.local/lib/python3.12/site-packages/airflow/utils/cli.py", line 116, in wrapper
    return f(*args, **kwargs)
           ^^^^^^^^^^^^^^^^^^
  File "/home/airflow/.local/lib/python3.12/site-packages/airflow/cli/commands/task_command.py", line 483, in task_run
    task_return_code = _run_task_by_selected_method(args, _dag, ti)
                       ^^^^^^^^^^^^^^^^^^^^^^^^^^^^^^^^^^^^^^^^^^^^
  File "/home/airflow/.local/lib/python3.12/site-packages/airflow/cli/commands/task_command.py", line 256, in _run_task_by_selected_method
    return _run_raw_task(args, ti)
           ^^^^^^^^^^^^^^^^^^^^^^^
  File "/home/airflow/.local/lib/python3.12/site-packages/airflow/cli/commands/task_command.py", line 341, in _run_raw_task
    return ti._run_raw_task(
           ^^^^^^^^^^^^^^^^^
  File "/home/airflow/.local/lib/python3.12/site-packages/airflow/utils/session.py", line 97, in wrapper
    return func(*args, session=session, **kwargs)
           ^^^^^^^^^^^^^^^^^^^^^^^^^^^^^^^^^^^^^^
  File "/home/airflow/.local/lib/python3.12/site-packages/airflow/models/taskinstance.py", line 3005, in _run_raw_task
    return _run_raw_task(
           ^^^^^^^^^^^^^^
  File "/home/airflow/.local/lib/python3.12/site-packages/airflow/models/taskinstance.py", line 273, in _run_raw_task
    TaskInstance._execute_task_with_callbacks(
  File "/home/airflow/.local/lib/python3.12/site-packages/airflow/models/taskinstance.py", line 3159, in _execute_task_with_callbacks
    result = self._execute_task(context, task_orig)
             ^^^^^^^^^^^^^^^^^^^^^^^^^^^^^^^^^^^^^^
  File "/home/airflow/.local/lib/python3.12/site-packages/airflow/models/taskinstance.py", line 3183, in _execute_task
    return _execute_task(self, context, task_orig)
           ^^^^^^^^^^^^^^^^^^^^^^^^^^^^^^^^^^^^^^^
  File "/home/airflow/.local/lib/python3.12/site-packages/airflow/models/taskinstance.py", line 767, in _execute_task
    result = _execute_callable(context=context, **execute_callable_kwargs)
             ^^^^^^^^^^^^^^^^^^^^^^^^^^^^^^^^^^^^^^^^^^^^^^^^^^^^^^^^^^^^^
  File "/home/airflow/.local/lib/python3.12/site-packages/airflow/models/taskinstance.py", line 733, in _execute_callable
    return ExecutionCallableRunner(
           ^^^^^^^^^^^^^^^^^^^^^^^^
  File "/home/airflow/.local/lib/python3.12/site-packages/airflow/utils/operator_helpers.py", line 252, in run
    return self.func(*args, **kwargs)
           ^^^^^^^^^^^^^^^^^^^^^^^^^^
  File "/home/airflow/.local/lib/python3.12/site-packages/airflow/models/baseoperator.py", line 417, in wrapper
    return func(self, *args, **kwargs)
           ^^^^^^^^^^^^^^^^^^^^^^^^^^^
  File "/home/airflow/.local/lib/python3.12/site-packages/airflow/operators/bash.py", line 276, in execute
    raise AirflowException(
airflow.exceptions.AirflowException: Bash command failed. The command returned a non-zero exit code 127.
[2024-12-05T19:48:14.783+0000] {local_task_job_runner.py:266} INFO - Task exited with return code 1
[2024-12-05T19:48:14.802+0000] {taskinstance.py:3895} INFO - 0 downstream tasks scheduled from follow-on schedule check
[2024-12-05T19:48:14.813+0000] {local_task_job_runner.py:245} INFO - ::endgroup::
