[2024-11-15T00:01:40.478+0000] {local_task_job_runner.py:123} INFO - ::group::Pre task execution logs
[2024-11-15T00:01:40.489+0000] {taskinstance.py:2613} INFO - Dependencies all met for dep_context=non-requeueable deps ti=<TaskInstance: data_ingestion_gcs_dag.format_to_parquet_task scheduled__2024-11-14T00:00:00+00:00 [queued]>
[2024-11-15T00:01:40.497+0000] {taskinstance.py:2613} INFO - Dependencies all met for dep_context=requeueable deps ti=<TaskInstance: data_ingestion_gcs_dag.format_to_parquet_task scheduled__2024-11-14T00:00:00+00:00 [queued]>
[2024-11-15T00:01:40.497+0000] {taskinstance.py:2866} INFO - Starting attempt 1 of 2
[2024-11-15T00:01:40.508+0000] {taskinstance.py:2889} INFO - Executing <Task(PythonOperator): format_to_parquet_task> on 2024-11-14 00:00:00+00:00
[2024-11-15T00:01:40.516+0000] {warnings.py:112} WARNING - /home/***/.local/lib/python3.12/site-packages/***/task/task_runner/standard_task_runner.py:70: DeprecationWarning: This process (pid=207) is multi-threaded, use of fork() may lead to deadlocks in the child.
  pid = os.fork()

[2024-11-15T00:01:40.523+0000] {standard_task_runner.py:72} INFO - Started process 208 to run task
[2024-11-15T00:01:40.520+0000] {standard_task_runner.py:104} INFO - Running: ['***', 'tasks', 'run', 'data_ingestion_gcs_dag', 'format_to_parquet_task', 'scheduled__2024-11-14T00:00:00+00:00', '--job-id', '4', '--raw', '--subdir', '/opt/***/dags/fds.py', '--cfg-path', '/tmp/tmp6dcy1253']
[2024-11-15T00:01:40.524+0000] {standard_task_runner.py:105} INFO - Job 4: Subtask format_to_parquet_task
[2024-11-15T00:01:40.570+0000] {task_command.py:467} INFO - Running <TaskInstance: data_ingestion_gcs_dag.format_to_parquet_task scheduled__2024-11-14T00:00:00+00:00 [running]> on host 55075eb74fe7
[2024-11-15T00:01:40.628+0000] {taskinstance.py:3132} INFO - Exporting env vars: AIRFLOW_CTX_DAG_OWNER='***' AIRFLOW_CTX_DAG_ID='data_ingestion_gcs_dag' AIRFLOW_CTX_TASK_ID='format_to_parquet_task' AIRFLOW_CTX_EXECUTION_DATE='2024-11-14T00:00:00+00:00' AIRFLOW_CTX_TRY_NUMBER='1' AIRFLOW_CTX_DAG_RUN_ID='scheduled__2024-11-14T00:00:00+00:00'
[2024-11-15T00:01:40.629+0000] {taskinstance.py:731} INFO - ::endgroup::
[2024-11-15T00:01:40.645+0000] {taskinstance.py:3311} ERROR - Task failed with exception
Traceback (most recent call last):
  File "/home/airflow/.local/lib/python3.12/site-packages/airflow/models/taskinstance.py", line 767, in _execute_task
    result = _execute_callable(context=context, **execute_callable_kwargs)
             ^^^^^^^^^^^^^^^^^^^^^^^^^^^^^^^^^^^^^^^^^^^^^^^^^^^^^^^^^^^^^
  File "/home/airflow/.local/lib/python3.12/site-packages/airflow/models/taskinstance.py", line 733, in _execute_callable
    return ExecutionCallableRunner(
           ^^^^^^^^^^^^^^^^^^^^^^^^
  File "/home/airflow/.local/lib/python3.12/site-packages/airflow/utils/operator_helpers.py", line 252, in run
    return self.func(*args, **kwargs)
           ^^^^^^^^^^^^^^^^^^^^^^^^^^
  File "/home/airflow/.local/lib/python3.12/site-packages/airflow/models/baseoperator.py", line 417, in wrapper
    return func(self, *args, **kwargs)
           ^^^^^^^^^^^^^^^^^^^^^^^^^^^
  File "/home/airflow/.local/lib/python3.12/site-packages/airflow/operators/python.py", line 238, in execute
    return_value = self.execute_callable()
                   ^^^^^^^^^^^^^^^^^^^^^^^
  File "/home/airflow/.local/lib/python3.12/site-packages/airflow/operators/python.py", line 256, in execute_callable
    return runner.run(*self.op_args, **self.op_kwargs)
           ^^^^^^^^^^^^^^^^^^^^^^^^^^^^^^^^^^^^^^^^^^^
  File "/home/airflow/.local/lib/python3.12/site-packages/airflow/utils/operator_helpers.py", line 252, in run
    return self.func(*args, **kwargs)
           ^^^^^^^^^^^^^^^^^^^^^^^^^^
  File "/opt/airflow/dags/fds.py", line 28, in format_to_parquet
    table = pv.read_csv(src_file)
            ^^^^^^^^^^^^^^^^^^^^^
  File "pyarrow/_csv.pyx", line 1256, in pyarrow._csv.read_csv
  File "pyarrow/_csv.pyx", line 1115, in pyarrow._csv._get_reader
  File "pyarrow/io.pxi", line 2188, in pyarrow.lib.get_input_stream
  File "pyarrow/io.pxi", line 2159, in pyarrow.lib.get_native_file
  File "pyarrow/io.pxi", line 1245, in pyarrow.lib.OSFile.__cinit__
  File "pyarrow/io.pxi", line 1257, in pyarrow.lib.OSFile._open_readable
  File "pyarrow/error.pxi", line 155, in pyarrow.lib.pyarrow_internal_check_status
  File "pyarrow/error.pxi", line 92, in pyarrow.lib.check_status
FileNotFoundError: [Errno 2] Failed to open local file './yellow_tripdata_2021-01.csv'. Detail: [errno 2] No such file or directory
[2024-11-15T00:01:40.654+0000] {taskinstance.py:1225} INFO - Marking task as UP_FOR_RETRY. dag_id=data_ingestion_gcs_dag, task_id=format_to_parquet_task, run_id=scheduled__2024-11-14T00:00:00+00:00, execution_date=20241114T000000, start_date=20241115T000140, end_date=20241115T000140
[2024-11-15T00:01:40.676+0000] {taskinstance.py:340} INFO - ::group::Post task execution logs
[2024-11-15T00:01:40.676+0000] {standard_task_runner.py:124} ERROR - Failed to execute job 4 for task format_to_parquet_task ([Errno 2] Failed to open local file './yellow_tripdata_2021-01.csv'. Detail: [errno 2] No such file or directory; 208)
Traceback (most recent call last):
  File "/home/airflow/.local/lib/python3.12/site-packages/airflow/task/task_runner/standard_task_runner.py", line 117, in _start_by_fork
    ret = args.func(args, dag=self.dag)
          ^^^^^^^^^^^^^^^^^^^^^^^^^^^^^
  File "/home/airflow/.local/lib/python3.12/site-packages/airflow/cli/cli_config.py", line 49, in command
    return func(*args, **kwargs)
           ^^^^^^^^^^^^^^^^^^^^^
  File "/home/airflow/.local/lib/python3.12/site-packages/airflow/utils/cli.py", line 116, in wrapper
    return f(*args, **kwargs)
           ^^^^^^^^^^^^^^^^^^
  File "/home/airflow/.local/lib/python3.12/site-packages/airflow/cli/commands/task_command.py", line 483, in task_run
    task_return_code = _run_task_by_selected_method(args, _dag, ti)
                       ^^^^^^^^^^^^^^^^^^^^^^^^^^^^^^^^^^^^^^^^^^^^
  File "/home/airflow/.local/lib/python3.12/site-packages/airflow/cli/commands/task_command.py", line 256, in _run_task_by_selected_method
    return _run_raw_task(args, ti)
           ^^^^^^^^^^^^^^^^^^^^^^^
  File "/home/airflow/.local/lib/python3.12/site-packages/airflow/cli/commands/task_command.py", line 341, in _run_raw_task
    return ti._run_raw_task(
           ^^^^^^^^^^^^^^^^^
  File "/home/airflow/.local/lib/python3.12/site-packages/airflow/utils/session.py", line 97, in wrapper
    return func(*args, session=session, **kwargs)
           ^^^^^^^^^^^^^^^^^^^^^^^^^^^^^^^^^^^^^^
  File "/home/airflow/.local/lib/python3.12/site-packages/airflow/models/taskinstance.py", line 3005, in _run_raw_task
    return _run_raw_task(
           ^^^^^^^^^^^^^^
  File "/home/airflow/.local/lib/python3.12/site-packages/airflow/models/taskinstance.py", line 273, in _run_raw_task
    TaskInstance._execute_task_with_callbacks(
  File "/home/airflow/.local/lib/python3.12/site-packages/airflow/models/taskinstance.py", line 3159, in _execute_task_with_callbacks
    result = self._execute_task(context, task_orig)
             ^^^^^^^^^^^^^^^^^^^^^^^^^^^^^^^^^^^^^^
  File "/home/airflow/.local/lib/python3.12/site-packages/airflow/models/taskinstance.py", line 3183, in _execute_task
    return _execute_task(self, context, task_orig)
           ^^^^^^^^^^^^^^^^^^^^^^^^^^^^^^^^^^^^^^^
  File "/home/airflow/.local/lib/python3.12/site-packages/airflow/models/taskinstance.py", line 767, in _execute_task
    result = _execute_callable(context=context, **execute_callable_kwargs)
             ^^^^^^^^^^^^^^^^^^^^^^^^^^^^^^^^^^^^^^^^^^^^^^^^^^^^^^^^^^^^^
  File "/home/airflow/.local/lib/python3.12/site-packages/airflow/models/taskinstance.py", line 733, in _execute_callable
    return ExecutionCallableRunner(
           ^^^^^^^^^^^^^^^^^^^^^^^^
  File "/home/airflow/.local/lib/python3.12/site-packages/airflow/utils/operator_helpers.py", line 252, in run
    return self.func(*args, **kwargs)
           ^^^^^^^^^^^^^^^^^^^^^^^^^^
  File "/home/airflow/.local/lib/python3.12/site-packages/airflow/models/baseoperator.py", line 417, in wrapper
    return func(self, *args, **kwargs)
           ^^^^^^^^^^^^^^^^^^^^^^^^^^^
  File "/home/airflow/.local/lib/python3.12/site-packages/airflow/operators/python.py", line 238, in execute
    return_value = self.execute_callable()
                   ^^^^^^^^^^^^^^^^^^^^^^^
  File "/home/airflow/.local/lib/python3.12/site-packages/airflow/operators/python.py", line 256, in execute_callable
    return runner.run(*self.op_args, **self.op_kwargs)
           ^^^^^^^^^^^^^^^^^^^^^^^^^^^^^^^^^^^^^^^^^^^
  File "/home/airflow/.local/lib/python3.12/site-packages/airflow/utils/operator_helpers.py", line 252, in run
    return self.func(*args, **kwargs)
           ^^^^^^^^^^^^^^^^^^^^^^^^^^
  File "/opt/airflow/dags/fds.py", line 28, in format_to_parquet
    table = pv.read_csv(src_file)
            ^^^^^^^^^^^^^^^^^^^^^
  File "pyarrow/_csv.pyx", line 1256, in pyarrow._csv.read_csv
  File "pyarrow/_csv.pyx", line 1115, in pyarrow._csv._get_reader
  File "pyarrow/io.pxi", line 2188, in pyarrow.lib.get_input_stream
  File "pyarrow/io.pxi", line 2159, in pyarrow.lib.get_native_file
  File "pyarrow/io.pxi", line 1245, in pyarrow.lib.OSFile.__cinit__
  File "pyarrow/io.pxi", line 1257, in pyarrow.lib.OSFile._open_readable
  File "pyarrow/error.pxi", line 155, in pyarrow.lib.pyarrow_internal_check_status
  File "pyarrow/error.pxi", line 92, in pyarrow.lib.check_status
FileNotFoundError: [Errno 2] Failed to open local file './yellow_tripdata_2021-01.csv'. Detail: [errno 2] No such file or directory
[2024-11-15T00:01:40.713+0000] {local_task_job_runner.py:266} INFO - Task exited with return code 1
[2024-11-15T00:01:40.810+0000] {taskinstance.py:3895} INFO - 0 downstream tasks scheduled from follow-on schedule check
[2024-11-15T00:01:40.822+0000] {local_task_job_runner.py:245} INFO - ::endgroup::
